Workbook

Sheet Leia-me
A1: Painel ClimaBrasil — Base de Dados Tratada
A2: Reconstrução e organização da base bruta 'pcb-raw-data' (TCU / ClimateScanner)
A5: O QUE FOI FEITO
A6: O arquivo original continha o CSV bruto do Painel ClimaBrasil colado em uma única coluna do Excel. Como vários
A7: comentários de auditores possuem quebras de linha dentro de campos entre aspas, o Excel havia fragmentado cada
A8: parágrafo em uma linha própria da planilha (5.399 linhas para o que deveriam ser ~1.400 registros). Os dados foram
A9: reconstruídos a partir do texto bruto, identificando o início de cada avaliação por seu padrão fixo de campos
A10: (id, eixo, data, versão, tipo de ente, nome, id do ente, componente, item, nota), separando corretamente cada
A11: registro em uma linha e preservando o comentário completo do auditor.
A13: ESTRUTURA DOS DADOS
A14: • 1.398 avaliações (1 linha = 1 item avaliado em 1 ente federativo)
A15: • 48 entes avaliados nesta base: estados/DF e capitais
... A39: Em 5 células de comentário (Amazonas G3-A, G4-C, G5-A, G6-C; Vitória G7-C), o texto contém a marca literal '#NAME?'. Isso já estava presente no arquivo original enviado (confirmado: 45 ocorrências no arquivo-fonte) — provavelmente um trecho iniciado por hífen foi interpretado como fórmula em uma edição anterior do arquivo e o conteúdo original não pôde ser recuperado. Não é um erro introduzido neste tratamento.

Sheet Resumo por Ente
A1: Tipo de Ente | B1: Nome do Ente | C1: Nº de Registros | D1: Itens com Nota Válida | E1: Nota Média Geral | F1: Nota Média — Governança | G1: Nota Média — Financiamento
A2: Estado | B2: Acre | C2: =COUNTIF(Dados!$G:$G,B2) -> 28 | D2: =COUNTIFS(Dados!$G:$G,B2,Dados!$M:$M,"<>") -> 28 | E2: =IFERROR(AVERAGEIFS(Dados!$M:$M,Dados!$G:$G,B2),"") -> 0.76160714 | F2: =IFERROR(AVERAGEIFS(Dados!$M:$M,Dados!$G:$G,B2,Dados!$B:$B,"Governança"),"") -> 0.85936842 | G2: =IFERROR(AVERAGEIFS(Dados!$M:$M,Dados!$G:$G,B2,Dados!$B:$B,"Financiamento"),"") -> 0.55522222
A3: Estado | B3: Alagoas | C3: =COUNTIF(Dados!$G:$G,B3) -> 28 | D3: =COUNTIFS(Dados!$G:$G,B3,Dados!$M:$M,"<>") -> 28 | E3: =IFERROR(AVERAGEIFS(Dados!$M:$M,Dados!$G:$G,B3),"") -> 0.51164286 | F3: =IFERROR(AVERAGEIFS(Dados!$M:$M,Dados!$G:$G,B3,Dados!$B:$B,"Governança"),"") -> 0.59615789 | G3: =IFERROR(AVERAGEIFS(Dados!$M:$M,Dados!$G:$G,B3,Dados!$B:$B,"Financiamento"),"") -> 0.33322222
A4: Estado | B4: Amapá | C4: =COUNTIF(Dados!$G:$G,B4) -> 28 | D4: =COUNTIFS(Dados!$G:$G,B4,Dados!$M:$M,"<>") -> 28 | E4: =IFERROR(AVERAGEIFS(Dados!$M:$M,Dados!$G:$G,B4),"") -> 0.48764286 | F4: =IFERROR(AVERAGEIFS(Dados!$M:$M,Dados!$G:$G,B4,Dados!$B:$B,"Governança"),"") -> 0.56089474 | G4: =IFERROR(AVERAGEIFS(Dados!$M:$M,Dados!$G:$G,B4,Dados!$B:$B,"Financiamento"),"") -> 0.333
A5: Estado | B5: Amazonas | C5: =COUNTIF(Dados!$G:$G,B5) -> 28 | D5: =COUNTIFS(Dados!$G:$G,B5,Dados!$M:$M,"<>") -> 28 | E5: =IFERROR(AVERAGEIFS(Dados!$M:$M,Dados!$G:$G,B5),"") -> 0.39253571 | F5: =IFERROR(AVERAGEIFS(Dados!$M:$M,Dados!$G:$G,B5,Dados!$B:$B,"Governança"),"") -> 0.45578947 | G5: =IFERROR(AVERAGEIFS(Dados!$M:$M,Dados!$G:$G,B5,Dados!$B:$B,"Financiamento"),"") -> 0.259
A6: Estado | B6: Bahia | C6: =COUNTIF(Dados!$G:$G,B6) -> 28 | D6: =COUNTIFS(Dados!$G:$G,B6,Dados!$M:$M,"<>") -> 28 | E6: =IFERROR(AVERAGEIFS(Dados!$M:$M,Dados!$G:$G,B6),"") -> 0.52353571 | F6: =IFERROR(AVERAGEIFS(Dados!$M:$M,Dados!$G:$G,B6,Dados!$B:$B,"Governança"),"") -> 0.63131579 | G6: =IFERROR(AVERAGEIFS(Dados!$M:$M,Dados!$G:$G,B6,Dados!$B:$B,"Financiamento"),"") -> 0.296
A7: Estado | B7: Ceará | C7: =COUNTIF(Dados!$G:$G,B7) -> 28 | D7: =COUNTIFS(Dados!$G:$G,B7,Dados!$M:$M,"<>") -> 28 | E7: =IFERROR(AVERAGEIFS(Dados!$M:$M,Dados!$G:$G,B7),"") -> 0.63064286 | F7: =IFERROR(AVERAGEIFS(Dados!$M:$M,Dados!$G:$G,B7,Dados!$B:$B,"Governança"),"") -> 0.73652632 | G7: =IFERROR(AVERAGEIFS(Dados!$M:$M,Dados!$G:$G,B7,Dados!$B:$B,"Financiamento"),"") -> 0.40711111
A8: Estado | B8: Espírito Santo | C8: =COUNTIF(Dados!$G:$G,B8) -> 28 | D8: =COUNTIFS(Dados!$G:$G,B8,Dados!$M:$M,"<>") -> 28 | E8: =IFERROR(AVERAGEIFS(Dados!$M:$M,Dados!$G:$G,B8),"") -> 0.42825 | F8: =IFERROR(AVERAGEIFS(Dados!$M:$M,Dados!$G:$G,B8,Dados!$B:$B,"Governança"),"") -> 0.47336842 | G8: =IFERROR(AVERAGEIFS(Dados!$M:$M,Dados!$G:$G,B8,Dados!$B:$B,"Financiamento"),"") -> 0.333
A9: Estado | B9: Goiás | C9: =COUNTIF(Dados!$G:$G,B9) -> 28 | D9: =COUNTIFS(Dados!$G:$G,B9,Dados!$M:$M,"<>") -> 28 | E9: =IFERROR(AVERAGEIFS(Dados!$M:$M,Dados!$G:$G,B9),"") -> 0.54735714 | F9: =IFERROR(AVERAGEIFS(Dados!$M:$M,Dados!$G:$G,B9,Dados!$B:$B,"Governança"),"") -> 0.63126316 | G9: =IFERROR(AVERAGEIFS(Dados!$M:$M,Dados!$G:$G,B9,Dados!$B:$B,"Financiamento"),"") -> 0.37022222
A10: Estado | B10: Maranhão | C10: =COUNTIF(Dados!$G:$G,B10) -> 28 | D10: =COUNTIFS(Dados!$G:$G,B10,Dados!$M:$M,"<>") -> 28 | E10: =IFERROR(AVERAGEIFS(Dados!$M:$M,Dados!$G:$G,B10),"") -> 0.77367857 | F10: =IFERROR(AVERAGEIFS(Dados!$M:$M,Dados!$G:$G,B10,Dados!$B:$B,"Governança"),"") -> 0.89463158 | G10: =IFERROR(AVERAGEIFS(Dados!$M:$M,Dados!$G:$G,B10,Dados!$B:$B,"Financiamento"),"") -> 0.51833333
A11: Estado | B11: Mato Grosso | C11: =COUNTIF(Dados!$G:$G,B11) -> 28 | D11: =COUNTIFS(Dados!$G:$G,B11,Dados!$M:$M,"<>") -> 28 | E11: =IFERROR(AVERAGEIFS(Dados!$M:$M,Dados!$G:$G,B11),"") -> 0.59496429 | F11: =IFERROR(AVERAGEIFS(Dados!$M:$M,Dados!$G:$G,B11,Dados!$B:$B,"Governança"),"") -> 0.66642105 | G11: =IFERROR(AVERAGEIFS(Dados!$M:$M,Dados!$G:$G,B11,Dados!$B:$B,"Financiamento"),"") -> 0.44411111
A12: Estado | B12: Mato Grosso do Sul | C12: =COUNTIF(Dados!$G:$G,B12) -> 28 | D12: =COUNTIFS(Dados!$G:$G,B12,Dados!$M:$M,"<>") -> 28 | E12: =IFERROR(AVERAGEIFS(Dados!$M:$M,Dados!$G:$G,B12),"") -> 0.49975 | F12: =IFERROR(AVERAGEIFS(Dados!$M:$M,Dados!$G:$G,B12,Dados!$B:$B,"Governança"),"") -> 0.50847368 | G12: =IFERROR(AVERAGEIFS(Dados!$M:$M,Dados!$G:$G,B12,Dados!$B:$B,"Financiamento"),"") -> 0.48133333
A13: Estado | B13: Minas Gerais | C13: =COUNTIF(Dados!$G:$G,B13) -> 28 | D13: =COUNTIFS(Dados!$G:$G,B13,Dados!$M:$M,"<>") -> 28 | E13: =IFERROR(AVERAGEIFS(Dados!$M:$M,Dados!$G:$G,B13),"") -> 0.84496429 | F13: =IFERROR(AVERAGEIFS(Dados!$M:$M,Dados!$G:$G,B13,Dados!$B:$B,"Governança"),"") -> 0.87694737 | G13: =IFERROR(AVERAGEIFS(Dados!$M:$M,Dados!$G:$G,B13,Dados!$B:$B,"Financiamento"),"") -> 0.77744444
... A51: Município | B51: Vitória | C51: =COUNTIF(Dados!$G:$G,B51) -> 28 | D51: =COUNTIFS(Dados!$G:$G,B51,Dados!$M:$M,"<>") -> 28 | E51: =IFERROR(AVERAGEIFS(Dados!$M:$M,Dados!$G:$G,B51),"") -> 0.14088462 | F51: =IFERROR(AVERAGEIFS(Dados!$M:$M,Dados!$G:$G,B51,Dados!$B:$B,"Governança"),"") -> 0.11752941 | G51: =IFERROR(AVERAGEIFS(Dados!$M:$M,Dados!$G:$G,B51,Dados!$B:$B,"Financiamento"),"") -> 0.185

Sheet Resumo por Pilar
A1: Eixo | B1: Componente | C1: Pilar | D1: Nº de Registros | E1: Itens com Nota Válida | F1: Nota Média
A2: Financiamento | B2: F1 | C2: Finanças e gastos públicos | D2: =COUNTIF(Dados!$C:$C,B2) -> 200 | E2: =COUNTIFS(Dados!$C:$C,B2,Dados!$M:$M,"<>") -> 200 | F2: =IFERROR(AVERAGEIFS(Dados!$M:$M,Dados!$C:$C,B2),"") -> 0.33478
A3: Financiamento | B3: F2 | C3: Captação de recursos | D3: =COUNTIF(Dados!$C:$C,B3) -> 150 | E3: =COUNTIFS(Dados!$C:$C,B3,Dados!$M:$M,"<>") -> 150 | F3: =IFERROR(AVERAGEIFS(Dados!$M:$M,Dados!$C:$C,B3),"") -> 0.44043624
A4: Financiamento | B4: F3 | C4: Mobilização de investimento privado | D4: =COUNTIF(Dados!$C:$C,B4) -> 100 | E4: =COUNTIFS(Dados!$C:$C,B4,Dados!$M:$M,"<>") -> 100 | F4: =IFERROR(AVERAGEIFS(Dados!$M:$M,Dados!$C:$C,B4),"") -> 0.27871429
A5: Governança | B5: G1 | C5: Quadro legal | D5: =COUNTIF(Dados!$C:$C,B5) -> 150 | E5: =COUNTIFS(Dados!$C:$C,B5,Dados!$M:$M,"<>") -> 150 | F5: =IFERROR(AVERAGEIFS(Dados!$M:$M,Dados!$C:$C,B5),"") -> 0.67980667
A6: Governança | B6: G2 | C6: Estrutura governamental | D6: =COUNTIF(Dados!$C:$C,B6) -> 149 | E6: =COUNTIFS(Dados!$C:$C,B6,Dados!$M:$M,"<>") -> 149 | F6: =IFERROR(AVERAGEIFS(Dados!$M:$M,Dados!$C:$C,B6),"") -> 0.65963265
A7: Governança | B7: G3 | C7: Gestão de riscos | D7: =COUNTIF(Dados!$C:$C,B7) -> 99 | E7: =COUNTIFS(Dados!$C:$C,B7,Dados!$M:$M,"<>") -> 99 | F7: =IFERROR(AVERAGEIFS(Dados!$M:$M,Dados!$C:$C,B7),"") -> 0.50489691
A8: Governança | B8: G4 | C8: Coordenação horizontal e vertical | D8: =COUNTIF(Dados!$C:$C,B8) -> 150 | E8: =COUNTIFS(Dados!$C:$C,B8,Dados!$M:$M,"<>") -> 150 | F8: =IFERROR(AVERAGEIFS(Dados!$M:$M,Dados!$C:$C,B8),"") -> 0.64147619
A9: Governança | B9: G5 | C9: Engajamento de partes interessadas | D9: =COUNTIF(Dados!$C:$C,B9) -> 100 | E9: =COUNTIFS(Dados!$C:$C,B9,Dados!$M:$M,"<>") -> 100 | F9: =IFERROR(AVERAGEIFS(Dados!$M:$M,Dados!$C:$C,B9),"") -> 0.63628
A10: Governança | B10: G6 | C10: Justiça climática | D10: =COUNTIF(Dados!$C:$C,B10) -> 150 | E10: =COUNTIFS(Dados!$C:$C,B10,Dados!$M:$M,"<>") -> 150 | F10: =IFERROR(AVERAGEIFS(Dados!$M:$M,Dados!$C:$C,B10),"") -> 0.38037838
A11: Governança | B11: G7 | C11: Atuação do Legislativo, Judiciário e Controle | D11: =COUNTIF(Dados!$C:$C,B11) -> 150 | E11: =COUNTIFS(Dados!$C:$C,B11,Dados!$M:$M,"<>") -> 150 | F11: =IFERROR(AVERAGEIFS(Dados!$M:$M,Dados!$C:$C,B11),"") -> 0.46045528

Sheet Dados
A1: ID Avaliação | B1: Eixo | C1: Componente | D1: Pilar | E1: Item | F1: Tipo de Ente | G1: Nome do Ente | H1: ID do Ente | I1: Data da Avaliação | J1: Versão | K1: Nota (Texto) | L1: Nota (Valor Original) | M1: Nota Numérica (p/ médias) | N1: Comentário do Auditor | O1: Justificativa de Confidencialidade | P1: Status
A2: 7876 | B2: Financiamento | C2: F1 | D2: Finanças e gastos públicos | E2: A | F2: Estado | G2: Acre | H2: 12 | I2: 45912.645 | J2: Versão de Avaliação 2025 | K2: Estágio avançado | L2: 1 | M2: =IF(K2="Sem progresso",0,IF(OR(K2="Não avaliado",K2="Não se aplica",K2=""),"",L2)) -> 1 | N2: No PPA é previsto um programa Específico 1460- Programa Ecossistema de Inivação Ambiental e Adaptação Climática, com orçamento em 2024: R$ 10.521.086,24 e 2025: R$ 10.856.375,97. O Programa 1459 - Regularização, controle e monitoramento ambiental, prevê o orçamento de 2024: R$ 11.157.652,57 - 2025: R$ 11.513.228,62 e tem como objetivo Desenvolver de forma ampla o monitoramento ambiental do estado do Acre (cobertura florestal, hidrometeorológico, queimadas, qualidade do ar e a dinâmica de uso e ocupação do solo). Há também o programa Infraestrutura e mobilidade Urbana que prevê o orçamento de 2024: R$ 246.234.833,46 - 2025: R$ 254.081.932,93 e tem como OBJETIVO ESPECÍFICO 5: Implantação e Urbanização de Parques e OBJETIVO ESPECÍFICO 6:Preservação das Encostas de Rios e Igarapés Programa 1453 - Saneia Acre, com objetivo de Ampliar a oferta de rede de distribuição de água potável e da rede coletora e de tratamento de esgoto em todos municípios do Estado. Orçamento previsto: 2024: R$ 62.277.884,85 - 2025: R$ 64.262.578,69 | P2: P
A3: 7881 | B3: Financiamento | C3: F1 | D3: Finanças e gastos públicos | E3: B | F3: Estado | G3: Acre | H3: 12 | I3: 45912.645 | J3: Versão de Avaliação 2025 | K3: Estágio intermediário | L3: 0.666 | M3: =IF(K3="Sem progresso",0,IF(OR(K3="Não avaliado",K3="Não se aplica",K3=""),"",L3)) -> 0.666 | N3: No PPA é possível identificar programas com nomes relacionados ao clima, mas não um sistema de classificação em seu orçamento (Programa 1460 - Ecossistema de Inivação Ambiental e Adaptação Climática, em outros programas). Já na LOA 2025 pode-se identificar, mensurar e classificar gastos direcionados para ações climáticas, como por exemplo no Anexo 7 - Lei 2030: Código: 18.541.1460. Especificação: ECOSSISTEMA DE INOVAÇÃO AMBIENTAl e Adaptação Climática. Projetos: 15.225.268,48 Não foi possivel encontrar ações que possam contribuir negativamente para os objetivos climáticos. Porém a LOA 2025, | P3: P
A4: 7884 | B4: Financiamento | C4: F1 | D4: Finanças e gastos públicos | E4: C | F4: Estado | G4: Acre | H4: 12 | I4: 45912.645 | J4: Versão de Avaliação 2025 | K4: Sem progresso | M4: =IF(K4="Sem progresso",0,IF(OR(K4="Não avaliado",K4="Não se aplica",K4=""),"",L4)) -> 0 | N4: Em algumas licitações no Acre, documentos como o DOF e o licenciamento de operação são exigidos para comprovar a origem e legalidade de produtos florestais. Embora não haja menção específica a um "selo verde" do Acre, o estado tem algumas poucas ações de sustentabilidade, como o Prêmio Socioambiental Chico Mendes. Porém, não foi possível constatar que esta seja uma pratica institucionalizada do Estado em sua rotina de contratações e compras. | P4: P
A5: 7967 | B5: Financiamento | C5: F1 | D5: Finanças e gastos públicos | E5: D | F5: Estado | G5: Acre | H5: 12 | I5: 45912.645 | J5: Versão de Avaliação 2025 | K5: Estágio intermediário | L5: 0.666 | M5: =IF(K5="Sem progresso",0,IF(OR(K5="Não avaliado",K5="Não se aplica",K5=""),"",L5)) -> 0.666 | N5: "O portal de transparencia apresenta os dados orçamentários da gestão ambiental como um todo, não sendo possível discriminar os gastos em programas específicos. O acesso é feito pelo endereço www.acreppp.org, onde é possível encontrar de forma precisa indicadores de desmatamento - que registrou uma redução de 66% no período de 12 anos
A6: 7968 | B6: Financiamento | C6: F2 | D6: Captação de recursos | E6: A | F6: Estado | G6: Acre | H6: 12 | I6: 45912.645 | J6: Versão de Avaliação 2025 | K6: Estágio intermediário | L6: 0.666 | M6: =IF(K6="Sem progresso",0,IF(OR(K6="Não avaliado",K6="Não se aplica",K6=""),"",L6)) -> 0.666 | N6: Governo do Acre alinha políticas públicas ambientais que serão executadas em parceria com governo federal e municípios. O Acre aderiu ao projeto Floresta+ Amazônia, do Ministério de Meio Ambiente (MMA), e já deu início ao processo de adesão para que produtores rurais possam ser remunerados por manterem suas florestas em pé para além do exigido por lei. O Governo do Acre tem estabelecido diversas parcerias com o governo federal para fortalecer políticas ambientais no estado, com foco na preservação da Amazônia e no combate ao desmatamento. Essas parcerias envolvem ações de regularização ambiental, restauração florestal, bioeconomia e enfrentamento aos efeitos das mudanças climáticas. O Fundo Brasil-ONU é uma parceria estratégica entre o Consórcio da Amazônia Legal (CAL), a ONU Brasil e o governo federal, com o objetivo de apoiar a implementação de soluções sustentáveis e inclusivas para os desafios da Amazônia. O Acre foi contemplado pelo Fundo Brasil-ONU para a Amazônia. São mais de R$ 15 milhões que serão investidos no fortalecimento da governança ambiental, na restauração florestal, segurança hídrica e na bioeconomia. Não foi possível encontrar um mapeamento sistemático oportunidades de adesão. | P6: P
A7: 7970 | B7: Financiamento | C7: F2 | D7: Captação de recursos | E7: B | F7: Estado | G7: Acre | H7: 12 | I7: 45912.645 | J7: Versão de Avaliação 2025 | K7: Estágio avançado | L7: 1 | M7: =IF(K7="Sem progresso",0,IF(OR(K7="Não avaliado",K7="Não se aplica",K7=""),"",L7)) -> 1 | N7: O Acre tem se destacado na adesão e implementação de programas e políticas federais relacionadas ao clima, com foco na redução do desmatamento, promoção da sustentabilidade e adaptação às mudanças climáticas. O estado tem recebido investimentos significativos do governo federal e parcerias internacionais para projetos ambientais, incluindo programas como REDD+ e a recuperação de áreas degradadas. O governo do Acre, por meio da Secretaria de Estado de Meio Ambiente (Sema), tem trabalhado para alinhar políticas públicas ambientais com o governo federal e os municípios. O Programa REM e o Projeto Rumo ao Desmatamento Ilegal Zero com o Fundo Amazônia reafirmam a posição de vanguarda do Acre na proteção do meio ambiente. Juntas, essas iniciativas possibilitarão ao governo estadual empregar mais de R$ 138 milhões, no próximo ano, em ações de fortalecimento das políticas de sustentabilidade florestal e combate ao desmatamento ilegal. | P7: P
A8: 7987 | B8: Financiamento | C8: F2 | D8: Captação de recursos | E8: C | F8: Estado | G8: Acre | H8: 12 | I8: 45912.645 | J8: Versão de Avaliação 2025 | K8: Estágio intermediário | L8: 0.666 | M8: =IF(K8="Sem progresso",0,IF(OR(K8="Não avaliado",K8="Não se aplica",K8=""),"",L8)) -> 0.666 | N8: O governo do Acre, em colaboração com o governo federal, realiza o monitoramento da execução físico-financeira das políticas ambientais no estado. O governo do Acre tem parceria com o Ministério do Meio Ambiente (MMA) e municípios para o desenvolvimento de políticas públicas ambientais. Projetos como o "Pagamento por Serviços Ambientais (PSA) Agricultor" e o "Floresta+ Amazônia" são exemplos de iniciativas conjuntas. O estado também busca recursos de outras fontes, como o Fundo Amazônia, para financiar projetos de conservação ambiental. As ações de mobilização de investimentos são monitoradas com regularidade e as informações disponibilizadas e encontradas atendem parcialmente os atributos 2 e 3. Os recursos do Programa REM ACre Fase II podem ser acompanhadas na página eletrônica do programa e são atualizadas e de fácil compreensão. | P8: P
A9: 7562 | B9: Financiamento | C9: F3 | D9: Mobilização de investimento privado | E9: A | F9: Estado | G9: Acre | H9: 12 | I9: 45912.645 | J9: Versão de Avaliação 2025 | K9: Estágio inicial | L9: 0.333 | M9: =IF(K9="Sem progresso",0,IF(OR(K9="Não avaliado",K9="Não se aplica",K9=""),"",L9)) -> 0.333 | N9: Acre capta mais de U$ 300 milhões para investimentos Na Conferência das Nações Unidas sobre as Mudanças Climáticas (COP27), no Egito, o Estado do Acre prospectou mais de U$ 300 milhões que irão garantir investimentos em políticas de sustentabilidade para os próximos 4 anos. Com a U.S. Agency for International Development (Usaid), estão previstos mais de U$ 250 mil para desenvolvimento de projetos voltados para a sustentabilidade e o reflorestamento, para o fortalecimento de cadeias produtivas locais e melhoria da qualidade de vida daqueles que vivem na floresta. parceria foi firmada com a Noruega para captação de U$ 8 milhões destinados à recuperação de áreas degradadas, melhoramento do uso do solo, a diversificação da produção, a melhoria da geração de renda e dos serviços ambientais e ecossistêmicos. Já o fundo canadense se dispôs a investir U$ 30 milhões para ações voltadas para a bioeconomia. A Mercuria Trading S.A., uma empresa privada suíça, se propôs a contribuir com as políticas de comando e controle do desmatamento e incêndios florestais, a fim de viabilizar a captação mais de U$ 2 milhões. O programa REM, financiado pelos governos alemão (Banco KfW) e inglês (Beis), disponibilizará mais de U$ 13 milhões para o Acre. transparência e preparação da população. | P9: P
A10: 7583 | B10: Financiamento | C10: F3 | D10: Mobilização de investimento privado | E10: B | F10: Estado | G10: Acre | H10: 12 | I10: 45912.645 | J10: Versão de Avaliação 2025 | K10: Sem progresso | M10: =IF(K10="Sem progresso",0,IF(OR(K10="Não avaliado",K10="Não se aplica",K10=""),"",L10)) -> 0 | N10: Não foram encontradas as ações de mobilização de investimento privado que sejam monitoradas regularmente e que a informação seja disponibilizada de forma a atender totalmente aos atributos de transparência, acessibilidade e usabilidade Não foram localizadas evidências que demonstrem a existência de tal sistema de monitoramento e transparencia para o investimento privado. | P10: P
A11: 9925 | B11: Financiamento | C11: F1 | D11: Finanças e gastos públicos | E11: A | F11: Estado | G11: Alagoas | H11: 27 | I11: 45951.8 | J11: Versão de Avaliação 2025 | K11: Estágio avançado | L11: 1 | M11: =IF(K11="Sem progresso",0,IF(OR(K11="Não avaliado",K11="Não se aplica",K11=""),"",L11)) -> 1 | N11: O PPA do Estado de Alagoas inclui o enfrentamento das mudanças climáticas como uma das suas diretrizes, alocando recursos em seus orçamentos anuais para ações ou iniciativas direcionadas ao enfrentamento da mudança do clima e seus impactos. Dentre as ações, pode-se citar: 1 - OPERAR, MANTER E AMPLIAR A REDE DE ESTAÇÕES METEOROLÓGICAS, HIDROLÓGICAS E PLUVIOMÉTRICAS DO SISTEMA DE MONITORAMENTO DE DESASTRES NATURAIS NO ESTADO DE ALAGOAS. 2 - CONSTRUIR BARRAGENS E REALIZAR AÇÕES DE PREVENÇÕES DE DESASTRES AMBIENTAIS NAS BACIAS HIDROGRÁFICAS. 3 - CONSCIENTIZAR A POPULAÇÃO E DISSERMINAR INFORMAÇÕES SOBRE A IMPORTÂNCIA DE SE PRESERVAR O MEIO AMBIENTE. 4 - IMPLANTAR E PROMOVER A POLÍTICA DE EDUCAÇÃO AMBIENTAL NO ESTADO, GARANTINDO A CONSERVAÇÃO E A MANUTENÇÃO DA BIODIVERSIDADE, PROMOVENDO A CONSERVAÇÃO DOS SOLOS, A PRODUÇÃO AGRÍCOLA, A BIODIVERSIDADE E A CONVIVÊNCIA SUSTENTAVÉL COM A SEMIARIDEZ EM REGIÕES SUSCETÍVEIS À DESERTIFICAÇÃO, E PROMOVENDO DIRETRIZES GERAIS DE DISCIPLINAMENTO DE USO E OCUPAÇÃO NATURAL E ECONÔNICA DA ZONA COSTEIRA. 5 - ELABORAR O PLANO DE AÇÃO CLIMÁTICA, OBJETIVANDO CRIAR ESTRATÉGIAS VOLTADAS ÀS MUDANÇAS CLIMÁTICAS. 6 - MANTER A SALA DE ALERTA E O SISTEMA DE ALERTA CLIMÁTICO DE ALAGOAS. | P11: P
A12: 9961 | B12: Financiamento | C12: F1 | D12: Finanças e gastos públicos | E12: B | F12: Estado | G12: Alagoas | H12: 27 | I12: 45951.8 | J12: Versão de Avaliação 2025 | K12: Sem progresso | M12: =IF(K12="Sem progresso",0,IF(OR(K12="Não avaliado",K12="Não se aplica",K12=""),"",L12)) -> 0 | N12: Conforme resposta do jurisdicionado ao RI, bem como após analisar o QDD 2024 e 2025, verifica-se que não há uma metodologia para identificar, mensurar e classificar os gastos direcionados a ações climáticas no orçamento. Os códigos ou rubricas são variados, não diferenciando os gastos diretos em ações climáticas de outros tipos de despesa administrativas ou setorial. Desse modo, não é possível o atendimento aos critérios de 1 a 4 da metodologia do Painel ClimaBrasil. | P12: P
A13: 9926 | B13: Financiamento | C13: F1 | D13: Finanças e gastos públicos | E13: C | F13: Estado | G13: Alagoas | H13: 27 | I13: 45951.8 | J13: Versão de Avaliação 2025 | K13: Estágio intermediário | L13: 0.666 | M13: =IF(K13="Sem progresso",0,IF(OR(K13="Não avaliado",K13="Não se aplica",K13=""),"",L13)) -> 0.666 | N13: A Lei nº 9.304/2024 estabelece como objetivos a redução das emissões de GEE e a promoção de ações de adaptação às mudanças climáticas, incluindo: 1. Implementação de ações de prevenção e adaptação às alterações produzidas pelos impactos das mudanças climáticas, visando proteger principalmente os estratos mais vulneráveis da população. 2. Promoção de compras e contratações sustentáveis pelo Poder Público, com base em critérios de sustentabilidade, em particular com vistas ao equilíbrio climático. Neste mesmo sentido, o Estado de Alagoas tem investido na capacitação técnica para viabilizar a inclusão de critérios de sustentabilidade nas compras públicas. Destaca-se a exigência de Declaração de Sustentabilidade nos editais, conforme a lei 14.133/21 Por fim, o Selo Alagoas pelo Clima reconhece publicamente as organizações que realizam e registram seus inventários de emissões de GEE, promovendo a adoção de boas práticas e a descarbonização de seus processos. Em relação aos critérios relacionados à redução de GEE e adaptação às mudanças climáticas nas compras públicas estaduais, há indicativos de ações concretas como a aquisição de Aquisição de Arla 32 para frota a diesel, a fim de reduzir emissões de óxidos de nitrogênio (NOx). | P13: P
A14: 9962 | B14: Financiamento | C14: F1 | D14: Finanças e gastos públicos | E14: D | F14: Estado | G14: Alagoas | H14: 27 | I14: 45951.8 | J14: Versão de Avaliação 2025 | K14: Sem progresso | M14: =IF(K14="Sem progresso",0,IF(OR(K14="Não avaliado",K14="Não se aplica",K14=""),"",L14)) -> 0 | N14: Não há marcador climático no orçamento. Desse modo, este item fica prejudicado. Ademais, as evidências apresentadas pelo ente jurisdicionado, bem como as pesquisas efetuadas pela Equipe de Auditoria em sites oficiais, não foram adequadas e suficientes para comprovar o atendimento aos critérios do item, conforme a Metodologia do Painel ClimaBrasil. | P14: P
A15: 9927 | B15: Financiamento | C15: F2 | D15: Captação de recursos | E15: A | F15: Estado | G15: Alagoas | H15: 27 | I15: 45951.8 | J15: Versão de Avaliação 2025 | K15: Estágio inicial | L15: 0.333 | M15: =IF(K15="Sem progresso",0,IF(OR(K15="Não avaliado",K15="Não se aplica",K15=""),"",L15)) -> 0.333 | N15: AdaptaCidades: Adesão formalizada, com previsão de apoio técnico a municípios, mas sem publicação de plano de ação estadual Plano ABC+ Alagoas: Lançado, porém ainda em fase inicial de execução (sem metas monitoradas publicamente) No entanto, não há registro público de um mapeamento sistemático ou documento estadual que organize de forma integrada todas as oportunidades de financiamento climático, sejam federais, multilaterais (como GCF, BID, BNDES Fundo Clima) ou por meio de políticas setoriais. Quanto a capacidade operacional, algumas ações são descentralizadas em diferentes secretarias/órgãos (Meio Ambiente, Infraestrutura, Agricultura, IMA), levando a atuações isoladas, o que dificulta a integração das informações geradas pelos diferentes atores. | P15: P
A16: 9963 | B16: Financiamento | C16: F2 | D16: Captação de recursos | E16: B | F16: Estado | G16: Alagoas | H16: 27 | I16: 45951.8 | J16: Versão de Avaliação 2025 | K16: Sem progresso | M16: =IF(K16="Sem progresso",0,IF(OR(K16="Não avaliado",K16="Não se aplica",K16=""),"",L16)) -> 0 | N16: Conforme respostas fornecidas pelo jurisdicionado ao RI, na página 30: "Há iniciativas de apresentação de projetos em Brasília e captação de recursos (ex.: ações conjuntas com SERFI para transição energética e projetos estruturantes)". Não foram fornecidos mapeamentos ou informações adicionais sobre os projetos/oportunidades de financiamento atualmente buscados/identificados pelo governo de Alagoas, sendo evidenciado apenas que havia iniciativas a serem apresentadas, mas nada concretizado até a presente avaliação. | P16: P
A17: 9964 | B17: Financiamento | C17: F2 | D17: Captação de recursos | E17: C | F17: Estado | G17: Alagoas | H17: 27 | I17: 45951.8 | J17: Versão de Avaliação 2025 | K17: Sem progresso | M17: =IF(K17="Sem progresso",0,IF(OR(K17="Não avaliado",K17="Não se aplica",K17=""),"",L17)) -> 0 | N17: Não foram identificadas/fornecidas evidências de que há ações para a captação de recursos para execução de ações de política climática monitoradas de modo contínuo e/ou regular (ao menos uma vez). Não foram identificados/fornecidas evidências de que há sistemas, relatórios, websites ou outras ferramentas ou plataformas específicas (mecanismos) que apresentem dados sobre a captação de recursos para execução de ações de política climática de modo contínuo, com dados atualizados e disponíveis para pesquisa e auditoria (transparência ativa). | P17: P
A18: 9928 | B18: Financiamento | C18: F3 | D18: Mobilização de investimento privado | E18: A | F18: Estado | G18: Alagoas | H18: 27 | I18: 45951.8 | J18: Versão de Avaliação 2025 | K18: Estágio avançado | L18: 1 | M18: =IF(K18="Sem progresso",0,IF(OR(K18="Não avaliado",K18="Não se aplica",K18=""),"",L18)) -> 1 | N18: As evidências demonstram a existência de pelo menos dois mecanismos operacionais: 1. O Programa Cresce Alagoas, que oferece incentivos tributários. 2. O Programa Estadual de Pagamento por Serviços Ambientais (PROPSA), com editais lançados e em fase de pagamento. Assim, há evidências de que o ente mobilizou recursos privados em ações que contribuem para o alcance dos objetivos climáticos (nos exercícios de 2024-2025). A EXIGEN 1, biorrefinaria pioneira de biocombustíveis sustentáveis avançados do Brasil, fruto de uma aliança estratégica entre GranBio, Usina Caeté, Usina Santo Antônio e Impacto Bioenergia, é responsável por atrair investimentos da ordem de R$ 1,5 bilhão até 2028. | P18: P
A19: 9929 | B19: Financiamento | C19: F3 | D19: Mobilização de investimento privado | E19: B | F19: Estado | G19: Alagoas | H19: 27 | I19: 45951.8 | J19: Versão de Avaliação 2025 | K19: Sem progresso | M19: =IF(K19="Sem progresso",0,IF(OR(K19="Não avaliado",K19="Não se aplica",K19=""),"",L19)) -> 0 | N19: Não foram fornecidas evidências de atendimento a este critério pelo ente jurisdicionado. Também não ficou evidenciado se há ações para a mobilização de recursos privados para financiamento climático e, em havendo, se são monitoradas de modo contínuo e regular (ao menos uma vez ao ano) pelo Estado. | P19: P
A20: 6665 | B20: Financiamento | C20: F1 | D20: Finanças e gastos públicos | E20: A | F20: Estado | G20: Amapá | H20: 16 | I20: 45938.683 | J20: Versão de Avaliação 2025 | K20: Estágio intermediário | L20: 0.666 | M20: =IF(K20="Sem progresso",0,IF(OR(K20="Não avaliado",K20="Não se aplica",K20=""),"",L20)) -> 0.666 | N20: O PPA 2024-2027 e a LOA 2025 preveem programas e ações alinhados ao ODS 13, como "Governança Ambiental Sustentável" e "Tesouro Verde", com dotações específicas para políticas de clima e serviços ambientais. Contudo, os valores são reduzidos frente ao orçamento total, concentram-se na área ambiental e não há Plano Estadual de Mudanças Climáticas plenamente integrado. | P20: P
A21: 6666 | B21: Financiamento | C21: F1 | D21: Finanças e gastos públicos | E21: B | F21: Estado | G21: Amapá | H21: 16 | I21: 45938.683 | J21: Versão de Avaliação 2025 | K21: Sem progresso | M21: =IF(K21="Sem progresso",0,IF(OR(K21="Não avaliado",K21="Não se aplica",K21=""),"",L21)) -> 0 | N21: O Estado do Amapá não possui mecanismos formais para identificar e rastrear despesas orçamentárias, diretas ou indiretas, relacionadas a ações de mitigação/adaptação ou prejudiciais aos objetivos climáticos. As dotações existentes no PPA e LOA não estão classificadas como "gasto climático" nem integradas a sistema de monitoramento específico e tampouco foi demonstrado pela SEMA/AP em resposta oficial. | P21: P
A22: 6668 | B22: Financiamento | C22: F1 | D22: Finanças e gastos públicos | E22: C | F22: Estado | G22: Amapá | H22: 16 | I22: 45938.683 | J22: Versão de Avaliação 2025 | K22: Estágio inicial | L22: 0.333 | M22: =IF(K22="Sem progresso",0,IF(OR(K22="Não avaliado",K22="Não se aplica",K22=""),"",L22)) -> 0.333 | N22: Embora o Estado do Amapá possua o Manual Prático de Contratações Sustentáveis e base legal que prevê a adoção de critérios ambientais e climáticos, não há evidências consolidadas de aplicação sistemática e monitorada desses critérios nos processos licitatórios. As iniciativas identificadas concentram-se em orientações gerais e exemplos, mas sem comprovação de que sejam incorporadas de forma rotineira nos editais, contratos e licitações. | P22: P
A23: 6687 | B23: Financiamento | C23: F1 | D23: Finanças e gastos públicos | E23: D | F23: Estado | G23: Amapá | H23: 16 | I23: 45938.683 | J23: Versão de Avaliação 2025 | K23: Estágio inicial | L23: 0.333 | M23: =IF(K23="Sem progresso",0,IF(OR(K23="Não avaliado",K23="Não se aplica",K23=""),"",L23)) -> 0.333 | N23: O Estado do Amapá disponibiliza receitas e despesas em formato aberto (CSV), com dados detalhados e atualizados, atendendo à transparência ativa. Contudo, não há categorização específica para gastos climáticos ou contratações emergenciais, nem linguagem simplificada ou metadados que facilitem a compreensão pelo cidadão, | P23: P
A24: 6689 | B24: Financiamento | C24: F2 | D24: Captação de recursos | E24: A | F24: Estado | G24: Amapá | H24: 16 | I24: 45938.683 | J24: Versão de Avaliação 2025 | K24: Estágio intermediário | L24: 0.666 | M24: =IF(K24="Sem progresso",0,IF(OR(K24="Não avaliado",K24="Não se aplica",K24=""),"",L24)) -> 0.666 | N24: O Estado do Amapá demonstra capacidade de adesão a instrumentos e programas vinculados a planos climáticos e setoriais nacionais por meio da participação em iniciativas como o Programa de Consolidação do Pacto Nacional pela Gestão das Águas - Progestão e o Plano de Prevenção e Controle do Desmatamento na Amazônia Legal - PPCDAM. Devido à adesão comprovada e à implementação de medidas efetivas, mas com possibilidade de evolução para avançado mediante maior integração intersetorial e monitoramento ampliado. | P24: P
A25: 6692 | B25: Financiamento | C25: F2 | D25: Captação de recursos | E25: B | F25: Estado | G25: Amapá | H25: 16 | I25: 45938.683 | J25: Versão de Avaliação 2025 | K25: Estágio intermediário | L25: 0.666 | M25: =IF(K25="Sem progresso",0,IF(OR(K25="Não avaliado",K25="Não se aplica",K25=""),"",L25)) -> 0.666 | N25: Há evidências de execução local com participação da SEMA e parceiros técnicos, demonstrando capacidade de captar e aplicar recursos externos. Contudo, a escala ainda é limitada e concentrada em poucos programas, sem portfólio diversificado e sistemático que envolva fundos nacionais como Fundo Clima ou operações com BNDES e GCF. | P25: P
A26: 6695 | B26: Financiamento | C26: F2 | D26: Captação de recursos | E26: C | F26: Estado | G26: Amapá | H26: 16 | I26: 45938.683 | J26: Versão de Avaliação 2025 | K26: Sem progresso | M26: =IF(K26="Sem progresso",0,IF(OR(K26="Não avaliado",K26="Não se aplica",K26=""),"",L26)) -> 0 | N26: Não foram identificadas evidências de mecanismos específicos e operacionais no Estado do Amapá para monitorar e divulgar de forma sistemática informações sobre o uso de recursos captados em financiamentos climáticos, nem sobre os resultados obtidos com sua aplicação. | P26: P
A27: 6696 | B27: Financiamento | C27: F3 | D27: Mobilização de investimento privado | E27: A | F27: Estado | G27: Amapá | H27: 16 | I27: 45938.683 | J27: Versão de Avaliação 2025 | K27: Estágio inicial | L27: 0.333 | M27: =IF(K27="Sem progresso",0,IF(OR(K27="Não avaliado",K27="Não se aplica",K27=""),"",L27)) -> 0.333 | N27: O Estado do Amapá aprovou a Lei nº 3.152/2024, que concede isenção de IPVA para veículos elétricos e híbridos até 2026, configurando incentivo fiscal climático. Além disso, o Estado dispõe do Programa Tesouro Verde, criado para promover a valoração de ativos ambientais e atrair recursos privados destinados à conservação e ao desenvolvimento sustentável. Entretanto, o Tesouro Verde encontra-se paralisado desde o início de 2023, sem execução orçamentária, operacionalização de projetos ou evidências de resultados concretos. Dessa forma, embora haja mecanismos instituídos, a ausência de implementação prática | P27: P
A28: 6698 | B28: Financiamento | C28: F3 | D28: Mobilização de investimento privado | E28: B | F28: Estado | G28: Amapá | H28: 16 | I28: 45938.683 | J28: Versão de Avaliação 2025 | K28: Sem progresso | M28: =IF(K28="Sem progresso",0,IF(OR(K28="Não avaliado",K28="Não se aplica",K28=""),"",L28)) -> 0 | N28: Não foram identificadas evidências de que o Estado do Amapá possua mecanismos para monitorar a mobilização de financiamento climático privado ou para divulgar de forma sistemática os resultados obtidos com esses recursos. Não há registros públicos de relatórios, indicadores ou sistemas de acompanhamento específicos sobre investimentos privados em ações de mitigação ou adaptação. | P28: P
A29: 1887 | B29: Financiamento | C29: F1 | D29: Finanças e gastos públicos | E29: A | F29: Estado | G29: Amazonas | H29: 13 | I29: 45915.675 | J29: Versão de Avaliação 2025 | K29: Sem progresso | M29: =IF(K29="Sem progresso",0,IF(OR(K29="Não avaliado",K29="Não se aplica",K29=""),"",L29)) -> 0 | N29: Apesar de constar no Orçamento de 2025, a ação "Serviços Ambientais, Adaptação e Mitigação às Mudanças do Clima", o valor orçamentário alocado é de apenas R$ 1.054,00" | P29: P
A30: 1893 | B30: Financiamento | C30: F1 | D30: Finanças e gastos públicos | E30: B | F30: Estado | G30: Amazonas | H30: 13 | I30: 45915.675 | J30: Versão de Avaliação 2025 | K30: Estágio inicial | L30: 0.333 | M30: =IF(K30="Sem progresso",0,IF(OR(K30="Não avaliado",K30="Não se aplica",K30=""),"",L30)) -> 0.333 | N30: A estrutura apresentada no PPA possibilita apenas, identificar, mensurar e classificar os gastos direcionados a ações climaticas no orçamento. Não é possível diferenciar recursos diretors ou outros tipos de despesas administrativas setoriais, bem como recursos indiretos que contribuam para os objetivos climáticos. | P30: P
A31: 9366 | B31: Financiamento | C31: F1 | D31: Finanças e gastos públicos | E31: C | F31: Estado | G31: Amazonas | H31: 13 | I31: 45915.675 | J31: Versão de Avaliação 2025 | K31: Estágio inicial | L31: 0.333 | M31: =IF(K31="Sem progresso",0,IF(OR(K31="Não avaliado",K31="Não se aplica",K31=""),"",L31)) -> 0.333 | N31: O Estado adota em seus processos licitatórios, critérios de sustentabilidade. | P31: P
A32: 9355 | B32: Financiamento | C32: F1 | D32: Finanças e gastos públicos | E32: D | F32: Estado | G32: Amazonas | H32: 13 | I32: 45915.675 | J32: Versão de Avaliação 2025 | K32: Sem progresso | M32: =IF(K32="Sem progresso",0,IF(OR(K32="Não avaliado",K32="Não se aplica",K32=""),"",L32)) -> 0 | N32: Não existem sistemas, relatórios ou websites que possibilitem a consulta a dados sobre o orçamento climático. | P32: P
A33: 9357 | B33: Financiamento | C33: F2 | D33: Captação de recursos | E33: A | F33: Estado | G33: Amazonas | H33: 13 | I33: 45915.675 | J33: Versão de Avaliação 2025 | K33: Estágio intermediário | L33: 0.666 | M33: =IF(K33="Sem progresso",0,IF(OR(K33="Não avaliado",K33="Não se aplica",K33=""),"",L33)) -> 0.666 | N33: O Estado desenvolve ações relevantes no combate ao desmatamento, por meio do PPCDQ-AM | P33: P
A34: 9358 | B34: Financiamento | C34: F2 | D34: Captação de recursos | E34: B | F34: Estado | G34: Amazonas | H34: 13 | I34: 45915.675 | J34: Versão de Avaliação 2025 | K34: Estágio intermediário | L34: 0.666 | M34: =IF(K34="Sem progresso",0,IF(OR(K34="Não avaliado",K34="Não se aplica",K34=""),"",L34)) -> 0.666 | N34: O Estado tem mapeadas fontes de recursos e utiliza vários instrumentos, por meio de projetos elaborados por seus técnicos, para acessá-los. | P34: P
A35: 9451 | B35: Financiamento | C35: F2 | D35: Captação de recursos | E35: C | F35: Estado | G35: Amazonas | H35: 13 | I35: 45915.675 | J35: Versão de Avaliação 2025 | K35: Estágio inicial | L35: 0.333 | M35: =IF(K35="Sem progresso",0,IF(OR(K35="Não avaliado",K35="Não se aplica",K35=""),"",L35)) -> 0.333 | N35: Atende ao atributo 1 e parcialmente aos itens 1 e 2. | P35: P
A36: 9381 | B36: Financiamento | C36: F3 | D36: Mobilização de investimento privado | E36: A | F36: Estado | G36: Amazonas | H36: 13 | I36: 45915.675 | J36: Versão de Avaliação 2025 | K36: Sem progresso | M36: =IF(K36="Sem progresso",0,IF(OR(K36="Não avaliado",K36="Não se aplica",K36=""),"",L36)) -> 0 | N36: Não há ações nesse sentido. | P36: P
A37: 9382 | B37: Financiamento | C37: F3 | D37: Mobilização de investimento privado | E37: B | F37: Estado | G37: Amazonas | H37: 13 | I37: 45915.675 | J37: Versão de Avaliação 2025 | K37: Sem progresso | M37: =IF(K37="Sem progresso",0,IF(OR(K37="Não avaliado",K37="Não se aplica",K37=""),"",L37)) -> 0 | N37: Não há ações nesse sentido. | P37: P
A38: 1903 | B38: Financiamento | C38: F1 | D38: Finanças e gastos públicos | E38: A | F38: Estado | G38: Bahia | H38: 29 | I38: 45901.867 | J38: Versão de Avaliação 2025 | K38: Estágio intermediário | L38: 0.666 | M38: =IF(K38="Sem progresso",0,IF(OR(K38="Não avaliado",K38="Não se aplica",K38=""),"",L38)) -> 0.666 | N38: "O PPA vigente (2024 - 2027) prevê a execução do Programa Meio Ambiente e Mudança do Clima, que, dentre outros, objetiva a implementação de ações de adaptação e mitigação das mudanças climáticas. Dentre as iniciativas previstas estão: implementar a Política Estadual de Mudança do Clima
A39: 1890 | B39: Financiamento | C39: F1 | D39: Finanças e gastos públicos | E39: B | F39: Estado | G39: Bahia | H39: 29 | I39: 45901.867 | J39: Versão de Avaliação 2025 | K39: Estágio inicial | L39: 0.333 | M39: =IF(K39="Sem progresso",0,IF(OR(K39="Não avaliado",K39="Não se aplica",K39=""),"",L39)) -> 0.333 | N39: "Na LOA 2025, há ações de mitigação dos efeitos das mudanças climáticas: Implementar o plano Agricultura de Baixo Carbono ABC+Bahia (SDR)
A40: 1892 | B40: Financiamento | C40: F1 | D40: Finanças e gastos públicos | E40: C | F40: Estado | G40: Bahia | H40: 29 | I40: 45901.867 | J40: Versão de Avaliação 2025 | K40: Estágio inicial | L40: 0.333 | M40: =IF(K40="Sem progresso",0,IF(OR(K40="Não avaliado",K40="Não se aplica",K40=""),"",L40)) -> 0.333 | N40: A Auditoria identificou normativos que estabelecem critérios de sustentabilidade nas contratações públicas estaduais, não havendo, especificamente, critérios relacionados à redução de GEE e adaptação à mudança do clima. O Estado sancionou sua nova Lei de Licitações e Contratos (Lei 14.634/2023), alinhando-se a Lei Federal 14.133/2021, estabelecendo o desenvolvimento sustentável como um dos seus princípios. Identificou-se o Decreto Estadual nº 14.692/2013, que instituiu o Programa Est. de Compras Públicas sustentáveis e o Decreto nº 22.598/2024, que trata da elaboração dos ETP's para aquisição de bens e contratação de serviços pelos órgãos e entidades da Adm. Pública direta, autárquica e fundacional do Executivo baiano, determinando, em seu Art. 6º, que dentre os elementos obrigatórios no ETP deverá estar presente "descrição de possíveis impactos ambientais e respectivas medidas mitigadoras, incluídos requisitos de baixo consumo de energia e de outros recursos, bem como logística reversa para desfazimento e reciclagem de bens e refugos, quando aplicável". Verificou-se, ainda, a Instrução Normativa SAEB nº 015/2014, que orienta sobre sustentabilidade ambiental na aquisição de bens e contratações de serviços de Tecnologia da Informação e Comunicação e a Instrução Normativa SAEB 003/2024, que orienta os órgãos e entidades do Executivo Estadual quanto à elaboração dos ETPs, prevendo, em anexo único, , modelo padronizado que expressamente exige a avaliação de impactos ambientais. | P40: P
...
